Workbook

Sheet Start Here
A1: THE AEO AUDIT SPREADSHEET
A2: Companion to The AEO Playbook (2026 Edition)
A4: HOW TO USE THIS SPREADSHEET
A5: Step 1 | B5: Make a copy of this spreadsheet to your own Drive or computer. File > Make a copy (Google Sheets) or File > Save As (Excel).
A6: Step 2 | B6: Go to the 'Prompts' tab. Replace the placeholder prompts with 30 prompts your customers would actually ask AI. 10 category, 10 comparison, 10 problem-solution.
A7: Step 3 | B7: Go to the 'Results' tab. For each prompt, run it through ChatGPT, Claude, Perplexity, and Google AI Overviews. Log whether your brand was mentioned, your position, who beat you, and which sources were cited.
A8: Step 4 | B8: Check the 'Share of Voice' tab. It auto-calculates from your Results. This is your headline number.
A9: Step 5 | B9: Check the 'Competitor Map' tab. It shows you exactly who is winning your category.
A10: Step 6 | B10: Use the diagnosis to execute the 7 levers in Part 3 of the playbook.
A12: KEY CONCEPTS
A13: Share of Voice | B13: The % of AI answers in your category where your brand was named. Your headline number.
A14: Position | B14: Where you appeared in the AI's answer. 1 = named first (best). 2 = second. 3+ = mentioned later. 0 = not mentioned.
A15: Category prompts | B15: Broad discovery queries (e.g. 'best CRM for small business'). Hardest to win, biggest payoff.
A16: Comparison prompts | B16: Head-to-head queries (e.g. 'Brand X vs Brand Y'). Easiest to move with comparison content.
A17: Problem-solution prompts | B17: Customer-pain queries (e.g. 'how do I reduce churn'). Highest intent, often least competition.

Sheet Setup
A1: SETUP
A2: Fill in these fields before starting. They power the rest of the spreadsheet.
A4: Your Business Name | B4: [Enter your brand name exactly as you'd want AI to cite it]
A5: Your Website | B5: [yourwebsite.com]
A6: Your Category | B6: [e.g. men's running apparel, B2B CRM, marketing agency]
A7: Top Competitor 1 | B7: [Competitor name]
A8: Top Competitor 2 | B8: [Competitor name]
A9: Top Competitor 3 | B9: [Competitor name]
A10: Top Competitor 4 | B10: [Competitor name]
A11: Top Competitor 5 | B11: [Competitor name]
A12: Audit Date | B12: [YYYY-MM-DD]

Sheet Prompts
A1: 30 PROMPTS
A2: Replace placeholder prompts below with what your customers would actually ask AI.
A4: # | B4: Category | C4: Prompt
A5: 1 | B5: Category | C5: Best [your category] for [target customer]
A6: 2 | B6: Category | C6: Top [your category] in 2026
A7: 3 | B7: Category | C7: Best [your category] brands
A8: 4 | B8: Category | C8: Best [your category] for beginners
A9: 5 | B9: Category | C9: Best premium [your category]
A10: 6 | B10: Category | C10: Best affordable [your category]
A11: 7 | B11: Category | C11: Most popular [your category] right now
A12: 8 | B12: Category | C12: Best [your category] for [specific use case]
A13: 9 | B13: Category | C13: Top rated [your category]
A14: 10 | B14: Category | C14: Best [your category] alternatives to [market leader]
A15: 11 | B15: Comparison | C15: [Your brand] vs [Competitor 1]
A16: 12 | B16: Comparison | C16: [Your brand] vs [Competitor 2]
... A34: 30 | B34: Problem-Solution | C34: What's the difference between [option 1] and [option 2]

Sheet Results
A1: AUDIT RESULTS
A2: For each prompt, run it across all 4 engines. Log whether your brand appeared, your position, competitors named, and sources cited.
A4: # | B4: Category | C4: Prompt | D4: Engine | E4: Mentioned? (Y/N) | F4: Position (0-10) | G4: Competitors Named | H4: Sources Cited
A5: 1 | B5: =Prompts!B5 -> Category | C5: =Prompts!C5 -> Best [your category] for [target customer] | D5: ChatGPT
A6: 1 | B6: =Prompts!B5 -> Category | C6: =Prompts!C5 -> Best [your category] for [target customer] | D6: Claude
A7: 1 | B7: =Prompts!B5 -> Category | C7: =Prompts!C5 -> Best [your category] for [target customer] | D7: Perplexity
A8: 1 | B8: =Prompts!B5 -> Category | C8: =Prompts!C5 -> Best [your category] for [target customer] | D8: Google AI Overviews
A9: 2 | B9: =Prompts!B6 -> Category | C9: =Prompts!C6 -> Top [your category] in 2026 | D9: ChatGPT
A10: 2 | B10: =Prompts!B6 -> Category | C10: =Prompts!C6 -> Top [your category] in 2026 | D10: Claude
A11: 2 | B11: =Prompts!B6 -> Category | C11: =Prompts!C6 -> Top [your category] in 2026 | D11: Perplexity
A12: 2 | B12: =Prompts!B6 -> Category | C12: =Prompts!C6 -> Top [your category] in 2026 | D12: Google AI Overviews
A13: 3 | B13: =Prompts!B7 -> Category | C13: =Prompts!C7 -> Best [your category] brands | D13: ChatGPT
A14: 3 | B14: =Prompts!B7 -> Category | C14: =Prompts!C7 -> Best [your category] brands | D14: Claude
A15: 3 | B15: =Prompts!B7 -> Category | C15: =Prompts!C7 -> Best [your category] brands | D15: Perplexity
A16: 3 | B16: =Prompts!B7 -> Category | C16: =Prompts!C7 -> Best [your category] brands | D16: Google AI Overviews
A17: 4 | B17: =Prompts!B8 -> Category | C17: =Prompts!C8 -> Best [your category] for beginners | D17: ChatGPT
A18: 4 | B18: =Prompts!B8 -> Category | C18: =Prompts!C8 -> Best [your category] for beginners | D18: Claude
A19: 4 | B19: =Prompts!B8 -> Category | C19: =Prompts!C8 -> Best [your category] for beginners | D19: Perplexity
A20: 4 | B20: =Prompts!B8 -> Category | C20: =Prompts!C8 -> Best [your category] for beginners | D20: Google AI Overviews
A21: 5 | B21: =Prompts!B9 -> Category | C21: =Prompts!C9 -> Best premium [your category] | D21: ChatGPT
A22: 5 | B22: =Prompts!B9 -> Category | C22: =Prompts!C9 -> Best premium [your category] | D22: Claude
A23: 5 | B23: =Prompts!B9 -> Category | C23: =Prompts!C9 -> Best premium [your category] | D23: Perplexity
A24: 5 | B24: =Prompts!B9 -> Category | C24: =Prompts!C9 -> Best premium [your category] | D24: Google AI Overviews
A25: 6 | B25: =Prompts!B10 -> Category | C25: =Prompts!C10 -> Best affordable [your category] | D25: ChatGPT
A26: 6 | B26: =Prompts!B10 -> Category | C26: =Prompts!C10 -> Best affordable [your category] | D26: Claude
A27: 6 | B27: =Prompts!B10 -> Category | C27: =Prompts!C10 -> Best affordable [your category] | D27: Perplexity
A28: 6 | B28: =Prompts!B10 -> Category | C28: =Prompts!C10 -> Best affordable [your category] | D28: Google AI Overviews
A29: 7 | B29: =Prompts!B11 -> Category | C29: =Prompts!C11 -> Most popular [your category] right now | D29: ChatGPT
A30: 7 | B30: =Prompts!B11 -> Category | C30: =Prompts!C11 -> Most popular [your category] right now | D30: Claude
A31: 7 | B31: =Prompts!B11 -> Category | C31: =Prompts!C11 -> Most popular [your category] right now | D31: Perplexity
A32: 7 | B32: =Prompts!B11 -> Category | C32: =Prompts!C11 -> Most popular [your category] right now | D32: Google AI Overviews
A33: 8 | B33: =Prompts!B12 -> Category | C33: =Prompts!C12 -> Best [your category] for [specific use case] | D33: ChatGPT
A34: 8 | B34: =Prompts!B12 -> Category | C34: =Prompts!C12 -> Best [your category] for [specific use case] | D34: Claude
A35: 8 | B35: =Prompts!B12 -> Category | C35: =Prompts!C12 -> Best [your category] for [specific use case] | D35: Perplexity
A36: 8 | B36: =Prompts!B12 -> Category | C36: =Prompts!C12 -> Best [your category] for [specific use case] | D36: Google AI Overviews
A37: 9 | B37: =Prompts!B13 -> Category | C37: =Prompts!C13 -> Top rated [your category] | D37: ChatGPT
A38: 9 | B38: =Prompts!B13 -> Category | C38: =Prompts!C13 -> Top rated [your category] | D38: Claude
A39: 9 | B39: =Prompts!B13 -> Category | C39: =Prompts!C13 -> Top rated [your category] | D39: Perplexity
A40: 9 | B40: =Prompts!B13 -> Category | C40: =Prompts!C13 -> Top rated [your category] | D40: Google AI Overviews
A41: 10 | B41: =Prompts!B14 -> Category | C41: =Prompts!C14 -> Best [your category] alternatives to [market leader] | D41: ChatGPT
...

Sheet Share of Voice
A1: SHARE OF VOICE
A2: Auto-calculated from the Results tab. This is your headline number.
A4: OVERALL
A5: Total prompts run | B5: =COUNTIF(Results!E5:E124,"Y")+COUNTIF(Results!E5:E124,"N") -> 0
A6: Total mentions | B6: =COUNTIF(Results!E5:E124,"Y") -> 0
A7: Share of Voice (overall) | B7: =IFERROR(B6/B5,0) -> 0
A9: BY ENGINE
A10: Engine | B10: Mentions | C10: Total Prompts | D10: Share of Voice
A11: ChatGPT | B11: =COUNTIFS(Results!D5:D124,"ChatGPT",Results!E5:E124,"Y") -> 0 | C11: =COUNTIF(Results!D5:D124,"ChatGPT") -> 30 | D11: =IFERROR(B11/C11,0) -> 0
A12: Claude | B12: =COUNTIFS(Results!D5:D124,"Claude",Results!E5:E124,"Y") -> 0 | C12: =COUNTIF(Results!D5:D124,"Claude") -> 30 | D12: =IFERROR(B12/C12,0) -> 0
A13: Perplexity | B13: =COUNTIFS(Results!D5:D124,"Perplexity",Results!E5:E124,"Y") -> 0 | C13: =COUNTIF(Results!D5:D124,"Perplexity") -> 30 | D13: =IFERROR(B13/C13,0) -> 0
A14: Google AI Overviews | B14: =COUNTIFS(Results!D5:D124,"Google AI Overviews",Results!E5:E124,"Y") -> 0 | C14: =COUNTIF(Results!D5:D124,"Google AI Overviews") -> 30 | D14: =IFERROR(B14/C14,0) -> 0
A16: BY CATEGORY
A17: Category | B17: Mentions | C17: Total Prompts | D17: Share of Voice
A18: Category | B18: =COUNTIFS(Results!B5:B124,"Category",Results!E5:E124,"Y") -> 0 | C18: =COUNTIF(Results!B5:B124,"Category") -> 40 | D18: =IFERROR(B18/C18,0) -> 0
A19: Comparison | B19: =COUNTIFS(Results!B5:B124,"Comparison",Results!E5:E124,"Y") -> 0 | C19: =COUNTIF(Results!B5:B124,"Comparison") -> 40 | D19: =IFERROR(B19/C19,0) -> 0
A20: Problem-Solution | B20: =COUNTIFS(Results!B5:B124,"Problem-Solution",Results!E5:E124,"Y") -> 0 | C20: =COUNTIF(Results!B5:B124,"Problem-Solution") -> 40 | D20: =IFERROR(B20/C20,0) -> 0
A23: ENGINE x CATEGORY (DEEP DIVE)
A24: Engine | B24: Category | C24: Comparison | D24: Problem-Solution
A25: ChatGPT | B25: =IFERROR(COUNTIFS(Results!D5:D124,"ChatGPT",Results!B5:B124,"Category",Results!E5:E124,"Y")/COUNTIFS(Results!D5:D124,"ChatGPT",Results!B5:B124,"Category"),0) -> 0 | C25: =IFERROR(COUNTIFS(Results!D5:D124,"ChatGPT",Results!B5:B124,"Comparison",Results!E5:E124,"Y")/COUNTIFS(Results!D5:D124,"ChatGPT",Results!B5:B124,"Comparison"),0) -> 0 | D25: =IFERROR(COUNTIFS(Results!D5:D124,"ChatGPT",Results!B5:B124,"Problem-Solution",Results!E5:E124,"Y")/COUNTIFS(Results!D5:D124,"ChatGPT",Results!B5:B124,"Problem-Solution"),0) -> 0
A26: Claude | B26: =IFERROR(COUNTIFS(Results!D5:D124,"Claude",Results!B5:B124,"Category",Results!E5:E124,"Y")/COUNTIFS(Results!D5:D124,"Claude",Results!B5:B124,"Category"),0) -> 0 | C26: =IFERROR(COUNTIFS(Results!D5:D124,"Claude",Results!B5:B124,"Comparison",Results!E5:E124,"Y")/COUNTIFS(Results!D5:D124,"Claude",Results!B5:B124,"Comparison"),0) -> 0 | D26: =IFERROR(COUNTIFS(Results!D5:D124,"Claude",Results!B5:B124,"Problem-Solution",Results!E5:E124,"Y")/COUNTIFS(Results!D5:D124,"Claude",Results!B5:B124,"Problem-Solution"),0) -> 0
A27: Perplexity | B27: =IFERROR(COUNTIFS(Results!D5:D124,"Perplexity",Results!B5:B124,"Category",Results!E5:E124,"Y")/COUNTIFS(Results!D5:D124,"Perplexity",Results!B5:B124,"Category"),0) -> 0 | C27: =IFERROR(COUNTIFS(Results!D5:D124,"Perplexity",Results!B5:B124,"Comparison",Results!E5:E124,"Y")/COUNTIFS(Results!D5:D124,"Perplexity",Results!B5:B124,"Comparison"),0) -> 0 | D27: =IFERROR(COUNTIFS(Results!D5:D124,"Perplexity",Results!B5:B124,"Problem-Solution",Results!E5:E124,"Y")/COUNTIFS(Results!D5:D124,"Perplexity",Results!B5:B124,"Problem-Solution"),0) -> 0
A28: Google AI Overviews | B28: =IFERROR(COUNTIFS(Results!D5:D124,"Google AI Overviews",Results!B5:B124,"Category",Results!E5:E124,"Y")/COUNTIFS(Results!D5:D124,"Google AI Overviews",Results!B5:B124,"Category"),0) -> 0 | C28: =IFERROR(COUNTIFS(Results!D5:D124,"Google AI Overviews",Results!B5:B124,"Comparison",Results!E5:E124,"Y")/COUNTIFS(Results!D5:D124,"Google AI Overviews",Results!B5:B124,"Comparison"),0) -> 0 | D28: =IFERROR(COUNTIFS(Results!D5:D124,"Google AI Overviews",Results!B5:B124,"Problem-Solution",Results!E5:E124,"Y")/COUNTIFS(Results!D5:D124,"Google AI Overviews",Results!B5:B124,"Problem-Solution"),0) -> 0

Sheet Competitor Map
A1: COMPETITOR MAP
A2: Track every competitor you saw mentioned in the Results tab. Add their name and the spreadsheet will count their mentions vs yours.
A4: Competitor Brand | B4: Times Mentioned | C4: Share of Voice | D4: Notes
A5: =Setup!B7 -> [Competitor name] | B5: =IFERROR(SUMPRODUCT(--(ISNUMBER(SEARCH(A5,Results!G5:G124)))),0) -> 0 | C5: =IFERROR(B5/120,0) -> 0
A6: =Setup!B8 -> [Competitor name] | B6: =IFERROR(SUMPRODUCT(--(ISNUMBER(SEARCH(A6,Results!G5:G124)))),0) -> 0 | C6: =IFERROR(B6/120,0) -> 0
A7: =Setup!B9 -> [Competitor name] | B7: =IFERROR(SUMPRODUCT(--(ISNUMBER(SEARCH(A7,Results!G5:G124)))),0) -> 0 | C7: =IFERROR(B7/120,0) -> 0
A8: =Setup!B10 -> [Competitor name] | B8: =IFERROR(SUMPRODUCT(--(ISNUMBER(SEARCH(A8,Results!G5:G124)))),0) -> 0 | C8: =IFERROR(B8/120,0) -> 0
A9: =Setup!B11 -> [Competitor name] | B9: =IFERROR(SUMPRODUCT(--(ISNUMBER(SEARCH(A9,Results!G5:G124)))),0) -> 0 | C9: =IFERROR(B9/120,0) -> 0
B10: =IF(A10="",0,IFERROR(SUMPRODUCT(--(ISNUMBER(SEARCH(A10,Results!G5:G124)))),0)) -> 0 | C10: =IFERROR(B10/120,0) -> 0
B11: =IF(A11="",0,IFERROR(SUMPRODUCT(--(ISNUMBER(SEARCH(A11,Results!G5:G124)))),0)) -> 0 | C11: =IFERROR(B11/120,0) -> 0
B12: =IF(A12="",0,IFERROR(SUMPRODUCT(--(ISNUMBER(SEARCH(A12,Results!G5:G124)))),0)) -> 0 | C12: =IFERROR(B12/120,0) -> 0
B13: =IF(A13="",0,IFERROR(SUMPRODUCT(--(ISNUMBER(SEARCH(A13,Results!G5:G124)))),0)) -> 0 | C13: =IFERROR(B13/120,0) -> 0
B14: =IF(A14="",0,IFERROR(SUMPRODUCT(--(ISNUMBER(SEARCH(A14,Results!G5:G124)))),0)) -> 0 | C14: =IFERROR(B14/120,0) -> 0
B15: =IF(A15="",0,IFERROR(SUMPRODUCT(--(ISNUMBER(SEARCH(A15,Results!G5:G124)))),0)) -> 0 | C15: =IFERROR(B15/120,0) -> 0
B16: =IF(A16="",0,IFERROR(SUMPRODUCT(--(ISNUMBER(SEARCH(A16,Results!G5:G124)))),0)) -> 0 | C16: =IFERROR(B16/120,0) -> 0
B17: =IF(A17="",0,IFERROR(SUMPRODUCT(--(ISNUMBER(SEARCH(A17,Results!G5:G124)))),0)) -> 0 | C17: =IFERROR(B17/120,0) -> 0
B18: =IF(A18="",0,IFERROR(SUMPRODUCT(--(ISNUMBER(SEARCH(A18,Results!G5:G124)))),0)) -> 0 | C18: =IFERROR(B18/120,0) -> 0
B19: =IF(A19="",0,IFERROR(SUMPRODUCT(--(ISNUMBER(SEARCH(A19,Results!G5:G124)))),0)) -> 0 | C19: =IFERROR(B19/120,0) -> 0
B20: =IF(A20="",0,IFERROR(SUMPRODUCT(--(ISNUMBER(SEARCH(A20,Results!G5:G124)))),0)) -> 0 | C20: =IFERROR(B20/120,0) -> 0
B21: =IF(A21="",0,IFERROR(SUMPRODUCT(--(ISNUMBER(SEARCH(A21,Results!G5:G124)))),0)) -> 0 | C21: =IFERROR(B21/120,0) -> 0
B22: =IF(A22="",0,IFERROR(SUMPRODUCT(--(ISNUMBER(SEARCH(A22,Results!G5:G124)))),0)) -> 0 | C22: =IFERROR(B22/120,0) -> 0
B23: =IF(A23="",0,IFERROR(SUMPRODUCT(--(ISNUMBER(SEARCH(A23,Results!G5:G124)))),0)) -> 0 | C23: =IFERROR(B23/120,0) -> 0
B24: =IF(A24="",0,IFERROR(SUMPRODUCT(--(ISNUMBER(SEARCH(A24,Results!G5:G124)))),0)) -> 0 | C24: =IFERROR(B24/120,0) -> 0
A26: YOU | B26: =COUNTIF(Results!E5:E124,"Y") -> 0 | C26: =IFERROR(B26/120,0) -> 0 | D26: Your brand's total mentions across all prompts and engines

Sheet Action Plan
A1: ACTION PLAN
A2: Based on your audit findings, list the specific actions you'll take across the 7 levers. Prioritize by impact and effort.
A4: # | B4: Lever | C4: Specific Action | D4: Priority (1-5) | E4: Status
A5: 1 | B5: 1. Third-Party Authority Sites
A6: 2 | B6: 1. Third-Party Authority Sites
A7: 3 | B7: 1. Third-Party Authority Sites
A8: 4 | B8: 2. Reddit and Forums
A9: 5 | B9: 2. Reddit and Forums
A10: 6 | B10: 2. Reddit and Forums
A11: 7 | B11: 3. Comparison Content
A12: 8 | B12: 3. Comparison Content
A13: 9 | B13: 3. Comparison Content
A14: 10 | B14: 4. FAQ / Answer Content
A15: 11 | B15: 4. FAQ / Answer Content
A16: 12 | B16: 4. FAQ / Answer Content
... A25: 21 | B25: 7. Owned AI-Crawled Platforms
